<?xml version="1.0" ?>
<robot name="controlbot_1_imu" xmlns:xacro="http://www.ros.org/wiki/xacro">
<xacro:arg name="is_ignition" default="true"/>
<xacro:arg name="is_sim" default="true"/>


<xacro:include filename="$(find controlbot_1_imu_description)/urdf/materials.xacro" />
<xacro:include filename="$(find controlbot_1_imu_description)/urdf/controlbot_1_imu.trans" />
<xacro:include filename="$(find controlbot_1_imu_description)/urdf/controlbot_1_imu.gazebo" />
<xacro:include filename="$(find controlbot_1_imu_description)/urdf/ros2_control.xacro" />

<link name="base_footprint"/>
<link name="base_link">
    <inertial>
      <origin xyz="0.065 0 -0.056" rpy="0.0 0.25 0.3" />
      <mass value="1.1172857116478971"/>
      <inertia ixx="0.013874" iyy="0.013949" izz="0.014621" ixy="-9e-06" iyz="-2e-06" ixz="0.000161"/>
    </inertial>
  <visual>
    <origin xyz="0.065 0 -0.056" rpy="0 0 0"/>
    <geometry>
      <mesh filename="file://$(find controlbot_1_imu_description)/meshes/base_link.stl" scale="0.001 0.001 0.001"/>
    </geometry>
    <material name="dark_grey"/>
  </visual>
  <collision>
    <origin xyz="0.065 0 -0.056" rpy="0 0 0"/>
    <geometry>
      <mesh filename="file://$(find controlbot_1_imu_description)/meshes/base_link.stl" scale="0.001 0.001 0.001"/>
    </geometry>
  </collision>
  <material name=""/>
</link>

<link name="wheel_left_link_1">
    <inertial>
      <origin xyz="0.06525 -0.133 -0.056" rpy="0 0 0" />
      <mass value="0.16918711951069407" />
      <inertia ixx="0.000207" iyy="0.000378" izz="0.000207" ixy="0.0" iyz="-0.0" ixz="0.0"/>
    </inertial>
  <visual>
    <origin xyz="0.06525 -0.133 -0.056" rpy="0 0 0"/>
    <geometry>
      <mesh filename="file://$(find controlbot_1_imu_description)/meshes/wheel_left_link_1.stl" scale="0.001 0.001 0.001"/>
    </geometry>
    <material name="black"/>
  </visual>
  <collision>
    <origin xyz="0.06525 -0.133 -0.056" rpy="0 0 0"/>
    <geometry>
      <mesh filename="file://$(find controlbot_1_imu_description)/meshes/wheel_left_link_1.stl" scale="0.001 0.001 0.001"/>
    </geometry>
    <material name=""/>
  </collision>
</link>

<link name="wheel_right_link_1">
    <inertial>
      <origin xyz="0.06525 0.133 -0.056" rpy="0 0 0" />
      <mass value="0.16918711951069407" />
      <inertia ixx="0.000207" iyy="0.000378" izz="0.000207" ixy="0.0" iyz="-0.0" ixz="-0.0"/>
    </inertial>
  <visual>
    <origin xyz="0.06525 0.133 -0.056" rpy="0 0 0"/>
    <geometry>
      <mesh filename="file://$(find controlbot_1_imu_description)/meshes/wheel_right_link_1.stl" scale="0.001 0.001 0.001"/>
    </geometry>
    <material name="black"/>
  </visual>
  <collision>
    <origin xyz="0.06525 0.133 -0.056" rpy="0 0 0"/>
    <geometry>
      <mesh filename="file://$(find controlbot_1_imu_description)/meshes/wheel_right_link_1.stl" scale="0.001 0.001 0.001"/>
    </geometry>
    <material name=""/>
  </collision>
</link>

<link name="imu_link_1">
    <inertial>
      <origin xyz="0 -0.096 -0.123" rpy="0 0 0" />
      <mass value="0.0019979201495239213" />
      <inertia ixx="0.0" iyy="0.0" izz="0.0" ixy="-0.0" iyz="-0.0" ixz="-0.0"/>
    </inertial>
  <visual>
    <origin xyz="0 -0.096 -0.123" rpy="0 0 3.14"/>
    <geometry>
      <mesh filename="file://$(find controlbot_1_imu_description)/meshes/imu_link_1.stl" scale="0.001 0.001 0.001"/>
    </geometry>
    <material name="blue"/>
  </visual>
  <collision>
    <origin xyz="0 -0.096 -0.123" rpy="0 0 3.14"/>
    <geometry>
      <mesh filename="file://$(find controlbot_1_imu_description)/meshes/imu_link_1.stl" scale="0.001 0.001 0.001"/>
    </geometry>
    <material name=""/>
  </collision>
</link>
<link name="laser_link">
    <inertial>
      <origin xyz="0 -0.000381929217680526 -0.017064937812947" rpy="0 0 0" />
      <mass value="0.073084435549317" />
      <inertia ixx="1.96074931730795E-05" ixy="-3.62091076640009E-07" ixz="4.28230084046735E-07"
               iyy="2.40983835136327E-05" iyz="1.50180909250652E-08"
               izz="4.14184164228595E-05" />
    </inertial>
    <visual>
      <origin xyz="0 -0.000381929217680526 -0.017064937812947" rpy="0 0 0" />
      <geometry>
        <mesh filename="file://$(find controlbot_1_imu_description)/meshes/laser_link.STL" />
      </geometry>
      <material name="black"/>
    </visual>
    <collision>
      <origin xyz="0 -0.000381929217680526 -0.017064937812947" rpy="0 0 0" />
      <geometry>
        <mesh filename="file://$(find controlbot_1_imu_description)/meshes/laser_link.STL" />
      </geometry>
    </collision>
  </link>


<joint name="base_joint" type="fixed">
  <origin xyz="0 0 0.056" rpy="0 0 0"/>
  <parent link="base_footprint"/>
  <child link="base_link"/>
</joint>

<joint name="wheel_left_joint" type="continuous">
  <origin xyz="0 0.133 0" rpy="0 0 0"/>
  <parent link="base_link"/>
  <child link="wheel_left_link_1"/>
  <axis xyz="-0.0 1.0 0.0"/>
</joint>

<joint name="wheel_right_joint" type="continuous">
  <origin xyz="0 -0.133 0" rpy="0 0 0"/>
  <parent link="base_link"/>
  <child link="wheel_right_link_1"/>
  <axis xyz="0.0 1.0 -0.0"/>
</joint>

<joint name="imu_joint" type="fixed">
  <origin xyz="0.065 -0.095 0.06714" rpy="0 0 0"/>
  <parent link="base_link"/>
  <child link="imu_link_1"/>
</joint>

<joint name="laser_joint" type="fixed">
    <origin xyz="0.065 0 0.246144" rpy="0 0 3.14" />
    <parent link="base_link" />
    <child link="laser_link" />
    <axis xyz="0 0 0" />
  </joint>



</robot>
