<?xml version="1.0" ?>
<robot name="controlbot_1_imu" xmlns:xacro="http://www.ros.org/wiki/xacro">

<xacro:arg name="is_ignition" default="true"/>

<xacro:include filename="$(find controlbot_1_imu_description)/urdf/materials.xacro"/>
<xacro:include filename="$(find controlbot_1_imu_description)/urdf/controlbot_1_imu.trans" />
<xacro:include filename="$(find controlbot_1_imu_description)/urdf/controlbot_1_imu.gazebo" />
<!--ROS2 Control-->
<xacro:include filename="$(find controlbot_1_imu_description)/urdf/controlbot_ros2_control.xacro"/>

<link name="base_link">
  <inertial>
    <origin xyz="-0.00025879000866563083 6.23198924990529e-05 0.10465970525122006" rpy="0 0 0"/>
    <mass value="1.1212507191009462"/>
    <inertia ixx="0.015867" iyy="0.015943" izz="0.014685" ixy="-9e-06" iyz="-2e-06" ixz="0.00016"/>
  </inertial>
  <visual>
    <origin xyz="0 0 0" rpy="0 0 0"/>
    <geometry>
      <mesh filename="file://$(find controlbot_1_imu_description)/meshes/base_link.stl" scale="0.001 0.001 0.001"/>
    </geometry>
    <material name="silver"/>
  </visual>
  <collision>
    <origin xyz="0 0 0" rpy="0 0 0"/>
    <geometry>
      <mesh filename="file://$(find controlbot_1_imu_description)/meshes/base_link.stl" scale="0.001 0.001 0.001"/>
    </geometry>
  </collision>
</link>

<link name="wheel_left_link_1">
  <inertial>
    <origin xyz="-1.3877787807814457e-17 0.001539434653235472 -0.0004285178755264324" rpy="0 0 0"/>
    <mass value="0.16918711951069407"/>
    <inertia ixx="0.000207" iyy="0.000378" izz="0.000207" ixy="0.0" iyz="-0.0" ixz="0.0"/>
  </inertial>
  <visual>
    <origin xyz="0.065 -0.158849 -0.056855" rpy="0 0 0"/>
    <geometry>
      <mesh filename="file://$(find controlbot_1_imu_description)/meshes/wheel_left_link_1.stl" scale="0.001 0.001 0.001"/>
    </geometry>
    <material name="silver"/>
  </visual>
  <collision>
    <origin xyz="0.065 -0.158849 -0.056855" rpy="0 0 0"/>
    <geometry>
      <mesh filename="file://$(find controlbot_1_imu_description)/meshes/wheel_left_link_1.stl" scale="0.001 0.001 0.001"/>
    </geometry>
  </collision>
</link>

<link name="wheel_right_link_1">
  <inertial>
    <origin xyz="-2.6922908347160046e-15 -0.0016995364726090367 -0.00042637503932518167" rpy="0 0 0"/>
    <mass value="0.16918711951069396"/>
    <inertia ixx="0.000207" iyy="0.000378" izz="0.000207" ixy="0.0" iyz="-0.0" ixz="-0.0"/>
  </inertial>
  <visual>
    <origin xyz="0.065 0.15854 -0.056855" rpy="0 0 0"/>
    <geometry>
      <mesh filename="file://$(find controlbot_1_imu_description)/meshes/wheel_right_link_1.stl" scale="0.001 0.001 0.001"/>
    </geometry>
    <material name="silver"/>
  </visual>
  <collision>
    <origin xyz="0.065 0.15854 -0.056855" rpy="0 0 0"/>
    <geometry>
      <mesh filename="file://$(find controlbot_1_imu_description)/meshes/wheel_right_link_1.stl" scale="0.001 0.001 0.001"/>
    </geometry>
  </collision>
</link>

<link name="imu_link_1">
  <inertial>
    <origin xyz="3.5990916440841465e-06 0.00012513548551613854 0.0016495620864326599" rpy="0 0 0"/>
    <mass value="0.0019979201495239213"/>
    <inertia ixx="0.0" iyy="0.0" izz="0.0" ixy="-0.0" iyz="-0.0" ixz="0.0"/>
  </inertial>
  <visual>
    <origin xyz="0.0 -7.4e-05 -0.026572" rpy="0 0 0"/>
    <geometry>
      <mesh filename="file://$(find controlbot_1_imu_description)/meshes/imu_link_1.stl" scale="0.001 0.001 0.001"/>
    </geometry>
    <material name="silver"/>
  </visual>
  <collision>
    <origin xyz="0.0 -7.4e-05 -0.026572" rpy="0 0 0"/>
    <geometry>
      <mesh filename="file://$(find controlbot_1_imu_description)/meshes/imu_link_1.stl" scale="0.001 0.001 0.001"/>
    </geometry>
  </collision>
</link>

<joint name="Revolute 5" type="continuous">
  <origin xyz="-0.065 0.158849 0.056855" rpy="0 0 0"/>
  <parent link="base_link"/>
  <child link="wheel_left_link_1"/>
  <axis xyz="-0.0 1.0 0.0"/>
</joint>

<joint name="Revolute 6" type="continuous">
  <origin xyz="-0.065 -0.15854 0.056855" rpy="0 0 0"/>
  <parent link="base_link"/>
  <child link="wheel_right_link_1"/>
  <axis xyz="0.0 1.0 -0.0"/>
</joint>

<joint name="Rigid 7" type="fixed">
  <origin xyz="0.0 7.4e-05 0.026572" rpy="0 0 0"/>
  <parent link="base_link"/>
  <child link="imu_link_1"/>
</joint>

</robot>
